Workbook
Name APP: 'DATOS Y RESPONSABLES ESCALAMIEN'!$B$40:$B$48
Name AWS: 'DATOS Y RESPONSABLES ESCALAMIEN'!$C$16:$C$26
Name AZURE: 'DATOS Y RESPONSABLES ESCALAMIEN'!$C$27:$C$29
Name GCP: 'DATOS Y RESPONSABLES ESCALAMIEN'!$C$30:$C$32
Name Microsoft: 'DATOS Y RESPONSABLES ESCALAMIEN'!$E$3:$E$4

Sheet Instrucciones

Sheet USUARIOS_EN_APLICATIVOS
D2: COMPAÑÍA MUNDIAL DE SEGUROS S.A.
D3: FORMATO SOLICITUD GESTIÓN DE USUARIOS EN APLICATIVOS
D4: GCR-4-R-002
B6: A. INFORMACIÓN BÁSICA PARA GESTIÓN USUARIOS EN APLICATIVOS
B8: Nombre completo* | C8: Angello Perilla Ampudia | K8: Documento de identidad* | L8: 1033753593
B10: Cargo* | C10: Gestor Especializado en Datos | K10: Área / Sucursal / CEN | L10: Indemnizaciones Salud
B12: Centro de costos (CECO)* | G12: Consecutivo presupuestal*
B14: Tipo de movimiento (cargo) | G14: Fecha de ingreso ( si es una vinculación) | O14: Requiere usuario de red | Q14: ¿El usuario será usado para un BOT?
B16: Acciones sobre el usuario* | G16: Cargo anterior (si es un traslado) | O16: Requiere usuario de correo
B19: ACCESOS A APLICATIVOS | K19: ACCESO A CONEXIÓN VPN - CITRIX
B21: Aplicación | C21: Uso de aplicación | E21: Perfil | F21: Rol | K21: Tipo
C23: =IFERROR(VLOOKUP(B23,'DATOS Y RESPONSABLES ESCALAMIEN'!$B$1:$C$13,2,FALSE),"") | K23: NOTA: -Los campos señalados con asterísco * son de diligenciamiento obligatorio. -Este formato debe ser diligenciado por el Líder directo del área y es responsable de definir los accesos registrados en este formulario de acuerdo con el perfil del cargo. -Recuerda que para la gestión de usuarios en los aplicativos no se aceptarán que los usuarios o perfiles se usen como usuarios espejo. Los usuarios son de uso personal y no se deben compartir a otros Mundialistas.
C24: =IFERROR(VLOOKUP(B24,'DATOS Y RESPONSABLES ESCALAMIEN'!$B$1:$C$13,2,FALSE),"")
C25: =IFERROR(VLOOKUP(B25,'DATOS Y RESPONSABLES ESCALAMIEN'!$B$1:$C$13,2,FALSE),"")
C26: =IFERROR(VLOOKUP(B26,'DATOS Y RESPONSABLES ESCALAMIEN'!$B$1:$C$13,2,FALSE),"")
C27: =IFERROR(VLOOKUP(B27,'DATOS Y RESPONSABLES ESCALAMIEN'!$B$1:$C$13,2,FALSE),"")
B29: ACCESO A UNIDADES COMPARTIDAS
B31: Ruta | F31: Tipo de acceso
B32: \\ibm-svrftp\Siniestros | F32: Lectura y escritura
B36: OBSERVACIONES ADICIONALES
B38: B. INFORMACIÓN BÁSICA PARA GESTIÓN USUARIOS EN AGILÍSIMO (WEBSOAT)
B40: Acciones sobre el usuario* | G40: Perfil o nivel solicitado | M40: NOTA: -El responsable hace referencia al nombre del asesor a quien se asigna el usuario. -Los campos señalados con asterísco * son de diligenciamiento obligatorio. -Este formato debe ser diligenciado por el Líder directo del área y es responsable de definir los accesos registrados en este formulario son de acuerdo al perfil del cargo -Recuerda que para la gestión de usuarios en los aplicativos no se aceptarán que los usuarios o perfiles se usen como usuarios espejo. Los usuarios son de uso personal y no se deben compartir a otros Mundialistas. - Cuando el usuario solicitado es de Seguros Mundial se debe diligenciar "Negocios Directos" en el campo nombre del intermediario.
B42: Nombre del responsable* | G42: Celular del responsable*
B44: Tipo de documento* | D44: No. de documento del responsable* | G44: Correo electrónico del responsable*
B46: Nombre del intermediario* | G46: Sucursal*
B48: Nombre del punto de venta*
B50: OBSERVACIONES ADICIONALES
B54: C. INFORMACIÓN BÁSICA PARA GESTIÓN USUARIOS EN NUBE
B56: Tipo de requerimiento* | G56: Tercero (Nombre del Proveedor si aplica)* | N56: NOTA: -Los campos señalados con asterísco * son de diligenciamiento obligatorio. -Para las solicitudes de nube se debera adjuntar en el Ticket de aranda el Vb de los responsables de cada Nube/Proyecto aprobando el requerimiento (Matriz de escalamiento). -Los campos "Centro de costos (CECO)" Y "Consecutivo Presupuestal" son de obligatorio diligenciamiento si la solicitud es para las nubes Azure Devops y/o BitBucket dado que los usuarios de estas nubes generan un costo. -Recuerda que para la gestión de usuarios en los aplicativos no se aceptarán que los usuarios o perfiles se usen como usuarios espejo. Los usuarios son de uso personal y no se deben compartir a otros Mundialistas.
B58: Correo Electronico* | G58: Nombre Del Colaborador*
B60: Infraestructura Nube* | G60: Proyecto
B62: Responsable según Matriz de escalamiento | D62: =IFERROR(VLOOKUP(D60&I60,'DATOS Y RESPONSABLES ESCALAMIEN'!$D$15:$E$38,2,FALSE),"")
B64: Centro de costos (CECO) | G64: Consecutivo presupuestal
B66: Perfil* | G66: Vigencia del usuario
B68: Otro tipo de perfil? | G68: Fecha de Desactivacion (si es Temporal)
B70: Tipo de Usuario*
B72: Describir la finalidad del usuario*:

Sheet DATOS Y RESPONSABLES ESCALAMIEN
B1: NOMBRE APLICACIÓN | C1: TIPO DE USUARIO
B2: Aranda | C2: Gestión de solicitudes Tecnología | E2: Suite de Microsoft
B3: Arriendos Web | C3: Comercialización | E3: Licenciamiento
B4: AuraQuantic | C4: Gestión de solicitudes Negocio | E4: Usuario
B5: Judiciales | C5: Comercialización
B6: Mi Ruta | C6: Gestión documentación interna
B7: Microsoft | C7: Suite de Microsoft
B8: Mundial Express | C8: Comercialización
B9: Pharos | C9: Comercialización (CORE)
B10: Portal Firma Electrónica | C10: Gestión de firmas digitales
B11: Salesforce | C11: CRM
B12: SARA | C12: Gestión de talento humano
B13: SISE | C13: Financiero (CORE)
B15: Infraestructura | C15: Proyecto | D15: concat | E15: Responsable
B16: AWS | C16: Consola | D16: =B16&C16 -> AWSConsola | E16: Oscar Peña / Accesos y licenciamiento / Riesgos
B17: AWS | C17: Arriendos WEB/Express | D17: =B17&C17 -> AWSArriendos WEB/Express | E17: Diana Fernandez Abril
B18: AWS | C18: Circular 040/Carnet Virtual | D18: =B18&C18 -> AWSCircular 040/Carnet Virtual | E18: Mario Niño
B19: AWS | C19: Concentrador de pagos | D19: =B19&C19 -> AWSConcentrador de pagos | E19: Gloria Zapata Produccion/Augusto Fagua QA
B20: AWS | C20: Ecommerce | D20: =B20&C20 -> AWSEcommerce | E20: Juan Camilo Ortiz / Anderson Villamizar
B21: AWS | C21: Radicador | D21: =B21&C21 -> AWSRadicador | E21: Fabian Silva
B22: AWS | C22: Seguro Tercero | D22: =B22&C22 -> AWSSeguro Tercero | E22: Juan Camilo Ortiz / Anderson Villamizar
B23: AWS | C23: Usuario Mundialista | D23: =B23&C23 -> AWSUsuario Mundialista | E23: Juan Camilo Ortiz / Anderson Villamizar
B24: AWS | C24: ESB | D24: =B24&C24 -> AWSESB | E24: Leonardo Wilches
B25: AWS | C25: DBA SARLAFT | D25: =B25&C25 -> AWSDBA SARLAFT | E25: Jose Salazar
B26: AWS | C26: Bloc Mercadeo | D26: =B26&C26 -> AWSBloc Mercadeo | E26: Luisa Fernanda Parada
B27: AZURE | C27: Consola | D27: =B27&C27 -> AZUREConsola | E27: Oscar Peña / Accesos y licenciamiento / Riesgos
... B32: GCP | C32: Base unica de clientes | D32: =B32&C32 -> GCPBase unica de clientes | E32: Oscar Peña / Accesos y licenciamiento / Riesgos
B33: Mulesoft | D33: =B33&C33 -> Mulesoft | E33: Leonardo Wilches
B34: AZURE Dev Ops | D34: =B34&C34 -> AZURE Dev Ops | E34: Sebastian Diaz Mahecha
B35: BitBucket | D35: =B35&C35 -> BitBucket | E35: Sebastian Diaz Mahecha
B36: Data Dog | D36: =B36&C36 -> Data Dog | E36: Daniel Galindo
B37: Postman | D37: =B37&C37 -> Postman | E37: Leonardo Wilches
B38: Hopex | D38: =B38&C38 -> Hopex | E38: Leonardo Wilches
B40: AWS
B41: AZURE
B42: GCP
B43: Mulesoft
B44: AZURE Dev Ops
B45: BitBucket
B46: Data Dog
...
